Workbook

Sheet Fleet Overview
A1: FLEET OVERVIEW — VEHICLES 2026
A2: At-a-glance summary of all fleet vehicles • Data pulls automatically from Service Log & Fuel Log
A4: VEHICLE | B4: TOTAL SERVICE COST | C4: # SERVICES | D4: LATEST MILEAGE | E4: AVG COST / SERVICE | F4: FUEL EFFICIENCY (MPG) | G4: COST / 1K MILES | H4: % OF FLEET COST
A5: COLDRV1 22 TOY COR | B5: =SUMIFS('Service Log'!I$2:I$500,'Service Log'!A$2:A$500,"COLDRV1 22 TOY COR") | C5: =COUNTIFS('Service Log'!A$2:A$500,"COLDRV1 22 TOY COR",'Service Log'!I$2:I$500,">0") | D5: =IFERROR(maxifs('Service Log'!C$2:C$500,'Service Log'!A$2:A$500,"COLDRV1 22 TOY COR"),"") | E5: =IFERROR(B5/C5,0) | F5: =IFERROR(SUMIFS('Fuel Log'!D$2:D$500,'Fuel Log'!A$2:A$500,"COLDRV1 22 TOY COR")/SUMIFS('Fuel Log'!C$2:C$500,'Fuel Log'!A$2:A$500,"COLDRV1 22 TOY COR"),"") | G5: =IFERROR(B5/(D5/1000),0) | H5: =IFERROR(B5/B$11,0)
A6: COLDRV2 17 NISSAN ALTIMA | B6: =SUMIFS('Service Log'!I$2:I$500,'Service Log'!A$2:A$500,"COLDRV2 17 NISSAN ALTIMA") | C6: =COUNTIFS('Service Log'!A$2:A$500,"COLDRV2 17 NISSAN ALTIMA",'Service Log'!I$2:I$500,">0") | D6: =IFERROR(maxifs('Service Log'!C$2:C$500,'Service Log'!A$2:A$500,"COLDRV2 17 NISSAN ALTIMA"),"") | E6: =IFERROR(B6/C6,0) | F6: =IFERROR(SUMIFS('Fuel Log'!D$2:D$500,'Fuel Log'!A$2:A$500,"COLDRV2 17 NISSAN ALTIMA")/SUMIFS('Fuel Log'!C$2:C$500,'Fuel Log'!A$2:A$500,"COLDRV2 17 NISSAN ALTIMA"),"") | G6: =IFERROR(B6/(D6/1000),0) | H6: =IFERROR(B6/B$11,0)
A7: COLDRV3 17 TOY PRIUS | B7: =SUMIFS('Service Log'!I$2:I$500,'Service Log'!A$2:A$500,"COLDRV3 17 TOY PRIUS") | C7: =COUNTIFS('Service Log'!A$2:A$500,"COLDRV3 17 TOY PRIUS",'Service Log'!I$2:I$500,">0") | D7: =IFERROR(maxifs('Service Log'!C$2:C$500,'Service Log'!A$2:A$500,"COLDRV3 17 TOY PRIUS"),"") | E7: =IFERROR(B7/C7,0) | F7: =IFERROR(SUMIFS('Fuel Log'!D$2:D$500,'Fuel Log'!A$2:A$500,"COLDRV3 17 TOY PRIUS")/SUMIFS('Fuel Log'!C$2:C$500,'Fuel Log'!A$2:A$500,"COLDRV3 17 TOY PRIUS"),"") | G7: =IFERROR(B7/(D7/1000),0) | H7: =IFERROR(B7/B$11,0)
A8: COLDRV4 2015 HONDA ACCORD | B8: =SUMIFS('Service Log'!I$2:I$500,'Service Log'!A$2:A$500,"COLDRV4 2015 HONDA ACCORD") | C8: =COUNTIFS('Service Log'!A$2:A$500,"COLDRV4 2015 HONDA ACCORD",'Service Log'!I$2:I$500,">0") | D8: =IFERROR(maxifs('Service Log'!C$2:C$500,'Service Log'!A$2:A$500,"COLDRV4 2015 HONDA ACCORD"),"") | E8: =IFERROR(B8/C8,0) | F8: =IFERROR(SUMIFS('Fuel Log'!D$2:D$500,'Fuel Log'!A$2:A$500,"COLDRV4 2015 HONDA ACCORD")/SUMIFS('Fuel Log'!C$2:C$500,'Fuel Log'!A$2:A$500,"COLDRV4 2015 HONDA ACCORD"),"") | G8: =IFERROR(B8/(D8/1000),0) | H8: =IFERROR(B8/B$11,0)
A9: COLDRV5 18 HONDA ACCORD | B9: =SUMIFS('Service Log'!I$2:I$500,'Service Log'!A$2:A$500,"COLDRV5 18 HONDA ACCORD") | C9: =COUNTIFS('Service Log'!A$2:A$500,"COLDRV5 18 HONDA ACCORD",'Service Log'!I$2:I$500,">0") | D9: =IFERROR(maxifs('Service Log'!C$2:C$500,'Service Log'!A$2:A$500,"COLDRV5 18 HONDA ACCORD"),"") | E9: =IFERROR(B9/C9,0) | F9: =IFERROR(SUMIFS('Fuel Log'!D$2:D$500,'Fuel Log'!A$2:A$500,"COLDRV5 18 HONDA ACCORD")/SUMIFS('Fuel Log'!C$2:C$500,'Fuel Log'!A$2:A$500,"COLDRV5 18 HONDA ACCORD"),"") | G9: =IFERROR(B9/(D9/1000),0) | H9: =IFERROR(B9/B$11,0)
A10: COLDRV8 21 TOY COR | B10: =SUMIFS('Service Log'!I$2:I$500,'Service Log'!A$2:A$500,"COLDRV8 21 TOY COR") | C10: =COUNTIFS('Service Log'!A$2:A$500,"COLDRV8 21 TOY COR",'Service Log'!I$2:I$500,">0") | D10: =IFERROR(maxifs('Service Log'!C$2:C$500,'Service Log'!A$2:A$500,"COLDRV8 21 TOY COR"),"") | E10: =IFERROR(B10/C10,0) | F10: =IFERROR(SUMIFS('Fuel Log'!D$2:D$500,'Fuel Log'!A$2:A$500,"COLDRV8 21 TOY COR")/SUMIFS('Fuel Log'!C$2:C$500,'Fuel Log'!A$2:A$500,"COLDRV8 21 TOY COR"),"") | G10: =IFERROR(B10/(D10/1000),0) | H10: =IFERROR(B10/B$11,0)
A11: FLEET TOTAL | B11: =SUM(B5:B10) | C11: =SUM(C5:C10) | H11: =SUM(H5:H10)
A13: COST BREAKDOWN BY SERVICE CATEGORY
A14: VEHICLE | B14: ROUTINE / WEAR ITEMS | C14: ENGINE & COOLING | D14: TRANSMISSION & DRIVETRAIN | E14: STEERING & SUSPENSION | F14: ELECTRICAL & OTHER MAJOR
A15: COLDRV1 22 TOY COR | B15: =SUMIFS('Service Log'!I$2:I$500,'Service Log'!A$2:A$500,"COLDRV1 22 TOY COR",'Service Log'!G$2:G$500,"Routine / Wear Items") | C15: =SUMIFS('Service Log'!I$2:I$500,'Service Log'!A$2:A$500,"COLDRV1 22 TOY COR",'Service Log'!G$2:G$500,"Engine & Cooling") | D15: =SUMIFS('Service Log'!I$2:I$500,'Service Log'!A$2:A$500,"COLDRV1 22 TOY COR",'Service Log'!G$2:G$500,"Transmission & Drivetrain") | E15: =SUMIFS('Service Log'!I$2:I$500,'Service Log'!A$2:A$500,"COLDRV1 22 TOY COR",'Service Log'!G$2:G$500,"Steering & Suspension") | F15: =SUMIFS('Service Log'!I$2:I$500,'Service Log'!A$2:A$500,"COLDRV1 22 TOY COR",'Service Log'!G$2:G$500,"Electrical & Other Major")
A16: COLDRV2 17 NISSAN ALTIMA | B16: =SUMIFS('Service Log'!I$2:I$500,'Service Log'!A$2:A$500,"COLDRV2 17 NISSAN ALTIMA",'Service Log'!G$2:G$500,"Routine / Wear Items") | C16: =SUMIFS('Service Log'!I$2:I$500,'Service Log'!A$2:A$500,"COLDRV2 17 NISSAN ALTIMA",'Service Log'!G$2:G$500,"Engine & Cooling") | D16: =SUMIFS('Service Log'!I$2:I$500,'Service Log'!A$2:A$500,"COLDRV2 17 NISSAN ALTIMA",'Service Log'!G$2:G$500,"Transmission & Drivetrain") | E16: =SUMIFS('Service Log'!I$2:I$500,'Service Log'!A$2:A$500,"COLDRV2 17 NISSAN ALTIMA",'Service Log'!G$2:G$500,"Steering & Suspension") | F16: =SUMIFS('Service Log'!I$2:I$500,'Service Log'!A$2:A$500,"COLDRV2 17 NISSAN ALTIMA",'Service Log'!G$2:G$500,"Electrical & Other Major")
A17: COLDRV3 17 TOY PRIUS | B17: =SUMIFS('Service Log'!I$2:I$500,'Service Log'!A$2:A$500,"COLDRV3 17 TOY PRIUS",'Service Log'!G$2:G$500,"Routine / Wear Items") | C17: =SUMIFS('Service Log'!I$2:I$500,'Service Log'!A$2:A$500,"COLDRV3 17 TOY PRIUS",'Service Log'!G$2:G$500,"Engine & Cooling") | D17: =SUMIFS('Service Log'!I$2:I$500,'Service Log'!A$2:A$500,"COLDRV3 17 TOY PRIUS",'Service Log'!G$2:G$500,"Transmission & Drivetrain") | E17: =SUMIFS('Service Log'!I$2:I$500,'Service Log'!A$2:A$500,"COLDRV3 17 TOY PRIUS",'Service Log'!G$2:G$500,"Steering & Suspension") | F17: =SUMIFS('Service Log'!I$2:I$500,'Service Log'!A$2:A$500,"COLDRV3 17 TOY PRIUS",'Service Log'!G$2:G$500,"Electrical & Other Major")
A18: COLDRV4 2015 HONDA ACCORD | B18: =SUMIFS('Service Log'!I$2:I$500,'Service Log'!A$2:A$500,"COLDRV4 2015 HONDA ACCORD",'Service Log'!G$2:G$500,"Routine / Wear Items") | C18: =SUMIFS('Service Log'!I$2:I$500,'Service Log'!A$2:A$500,"COLDRV4 2015 HONDA ACCORD",'Service Log'!G$2:G$500,"Engine & Cooling") | D18: =SUMIFS('Service Log'!I$2:I$500,'Service Log'!A$2:A$500,"COLDRV4 2015 HONDA ACCORD",'Service Log'!G$2:G$500,"Transmission & Drivetrain") | E18: =SUMIFS('Service Log'!I$2:I$500,'Service Log'!A$2:A$500,"COLDRV4 2015 HONDA ACCORD",'Service Log'!G$2:G$500,"Steering & Suspension") | F18: =SUMIFS('Service Log'!I$2:I$500,'Service Log'!A$2:A$500,"COLDRV4 2015 HONDA ACCORD",'Service Log'!G$2:G$500,"Electrical & Other Major")
A19: COLDRV5 18 HONDA ACCORD | B19: =SUMIFS('Service Log'!I$2:I$500,'Service Log'!A$2:A$500,"COLDRV5 18 HONDA ACCORD",'Service Log'!G$2:G$500,"Routine / Wear Items") | C19: =SUMIFS('Service Log'!I$2:I$500,'Service Log'!A$2:A$500,"COLDRV5 18 HONDA ACCORD",'Service Log'!G$2:G$500,"Engine & Cooling") | D19: =SUMIFS('Service Log'!I$2:I$500,'Service Log'!A$2:A$500,"COLDRV5 18 HONDA ACCORD",'Service Log'!G$2:G$500,"Transmission & Drivetrain") | E19: =SUMIFS('Service Log'!I$2:I$500,'Service Log'!A$2:A$500,"COLDRV5 18 HONDA ACCORD",'Service Log'!G$2:G$500,"Steering & Suspension") | F19: =SUMIFS('Service Log'!I$2:I$500,'Service Log'!A$2:A$500,"COLDRV5 18 HONDA ACCORD",'Service Log'!G$2:G$500,"Electrical & Other Major")
A20: COLDRV8 21 TOY COR | B20: =SUMIFS('Service Log'!I$2:I$500,'Service Log'!A$2:A$500,"COLDRV8 21 TOY COR",'Service Log'!G$2:G$500,"Routine / Wear Items") | C20: =SUMIFS('Service Log'!I$2:I$500,'Service Log'!A$2:A$500,"COLDRV8 21 TOY COR",'Service Log'!G$2:G$500,"Engine & Cooling") | D20: =SUMIFS('Service Log'!I$2:I$500,'Service Log'!A$2:A$500,"COLDRV8 21 TOY COR",'Service Log'!G$2:G$500,"Transmission & Drivetrain") | E20: =SUMIFS('Service Log'!I$2:I$500,'Service Log'!A$2:A$500,"COLDRV8 21 TOY COR",'Service Log'!G$2:G$500,"Steering & Suspension") | F20: =SUMIFS('Service Log'!I$2:I$500,'Service Log'!A$2:A$500,"COLDRV8 21 TOY COR",'Service Log'!G$2:G$500,"Electrical & Other Major")

Sheet Service Log
A1: SERVICE LOG — ALL VEHICLES
A2: Primary data entry sheet • Use column A filter to view a single vehicle • Dropdown menus in columns A, D, G
A3: VEHICLE | B3: DATE | C3: MILEAGE | D3: SERVICE TRIGGER | E3: NOTES | F3: SERVICE DETAILS | G3: SERVICE CATEGORY | H3: SHOP / VENDOR | I3: TOTAL COST | J3: INVOICE / REF #
A4: COLDRV1 22 TOY COR | B4: 45695 | C4: 31837 | D4: MAINTENANCE | F4: Brake fluid flush | G4: Routine / Wear Items | H4: Discount Tire | I4: 75.12 | J4: INV-21395
A5: COLDRV4 2015 HONDA ACCORD | B5: 45711 | C5: 107331 | D5: REPAIR | F5: Valve cover gasket | G5: Engine & Cooling | H5: Quick Lube Express | I5: 384.49 | J5: INV-88504
A6: COLDRV8 21 TOY COR | B6: 45711 | C6: 39577 | D6: MAINTENANCE | F6: O2 sensor replacement | G6: Electrical & Other Major | H6: Quick Lube Express | I6: 297.15 | J6: INV-51104
A7: COLDRV2 17 NISSAN ALTIMA | B7: 45721 | C7: 81966 | D7: MAINTENANCE | F7: Tire rotation + balance | G7: Routine / Wear Items | H7: Midas Auto | I7: 74.66 | J7: INV-46434
A8: COLDRV5 18 HONDA ACCORD | B8: 45723 | C8: 64737 | D8: REPAIR | F8: Brake pad replacement (front) | G8: Routine / Wear Items | H8: Jiffy Lube | I8: 272.26 | J8: INV-65519
A9: COLDRV8 21 TOY COR | B9: 45738 | C9: 40582 | D9: MAINTENANCE | F9: Spark plug replacement | G9: Routine / Wear Items | H9: Quick Lube Express | I9: 179.67 | J9: INV-76562
A10: COLDRV3 17 TOY PRIUS | B10: 45742 | C10: 85433 | D10: MAINTENANCE | F10: Tire rotation + balance | G10: Routine / Wear Items | H10: Discount Tire | I10: 69.8 | J10: INV-44438
A11: COLDRV8 21 TOY COR | B11: 45768 | C11: 42143 | D11: MAINTENANCE | F11: Spark plug replacement | G11: Routine / Wear Items | H11: Toyota of Columbus | I11: 135.28 | J11: INV-84668
A12: COLDRV1 22 TOY COR | B12: 45769 | C12: 32767 | D12: MAINTENANCE | F12: Cabin air filter | G12: Routine / Wear Items | H12: Discount Tire | I12: 48.06 | J12: INV-36062
A13: COLDRV4 2015 HONDA ACCORD | B13: 45772 | C13: 110132 | D13: MAINTENANCE | F13: Wheel bearing replacement | G13: Steering & Suspension | H13: Pep Boys | I13: 259.86 | J13: INV-84364
A14: COLDRV5 18 HONDA ACCORD | B14: 45795 | C14: 67449 | D14: BREAK DOWN | E14: Stalled at intersection | F14: Alignment | G14: Routine / Wear Items | H14: Toyota of Columbus | I14: 129.21 | J14: INV-17944
A15: COLDRV2 17 NISSAN ALTIMA | B15: 45799 | C15: 85369 | D15: REPAIR | F15: Battery replacement | G15: Routine / Wear Items | H15: Firestone | I15: 140.95 | J15: INV-99593
A16: COLDRV4 2015 HONDA ACCORD | B16: 45802 | C16: 111282 | D16: REPAIR | F16: Power steering fluid flush | G16: Steering & Suspension | H16: Honda Service Center | I16: 125.95 | J16: INV-96474
A17: COLDRV3 17 TOY PRIUS | B17: 45816 | C17: 88623 | D17: MAINTENANCE | F17: Brake pad replacement (rear) | G17: Routine / Wear Items | H17: Toyota of Columbus | I17: 226.24 | J17: INV-16175
A18: COLDRV8 21 TOY COR | B18: 45819 | C18: 45314 | D18: MAINTENANCE | F18: Wiper blade replacement | G18: Routine / Wear Items | H18: Meineke | I18: 36.43 | J18: INV-78522
A19: COLDRV2 17 NISSAN ALTIMA | B19: 45828 | C19: 88664 | D19: REPAIR | F19: Water pump replacement | G19: Engine & Cooling | H19: Midas Auto | I19: 390.85 | J19: INV-45382
A20: COLDRV3 17 TOY PRIUS | B20: 45850 | C20: 90049 | D20: REPAIR | F20: Tie rod end replacement | G20: Steering & Suspension | H20: Midas Auto | I20: 269.28 | J20: INV-60019
A21: COLDRV1 22 TOY COR | B21: 45858 | C21: 35285 | D21: MAINTENANCE | F21: Coolant flush | G21: Routine / Wear Items | H21: Honda Service Center | I21: 142.16 | J21: INV-65392
A22: COLDRV5 18 HONDA ACCORD | B22: 45858 | C22: 68696 | D22: MAINTENANCE | F22: Air filter replacement | G22: Routine / Wear Items | H22: Honda Service Center | I22: 29.21 | J22: INV-46509
A23: COLDRV2 17 NISSAN ALTIMA | B23: 45876 | C23: 92268 | D23: MAINTENANCE | F23: Radiator replacement | G23: Engine & Cooling | H23: Quick Lube Express | I23: 480.17 | J23: INV-51347
A24: COLDRV8 21 TOY COR | B24: 45879 | C24: 47182 | D24: MAINTENANCE | F24: Water pump replacement | G24: Engine & Cooling | H24: Honda Service Center | I24: 416.4 | J24: INV-98039
A25: COLDRV4 2015 HONDA ACCORD | B25: 45882 | C25: 114333 | D25: MAINTENANCE | F25: Headlight bulb replacement | G25: Routine / Wear Items | H25: Pep Boys | I25: 29.81 | J25: INV-80686
A26: COLDRV1 22 TOY COR | B26: 45921 | C26: 37223 | D26: MAINTENANCE | F26: AC recharge | G26: Electrical & Other Major | H26: Midas Auto | I26: 110.22 | J26: INV-22676
... A28: COLDRV3 17 TOY PRIUS | B28: 45929 | C28: 93016 | D28: MAINTENANCE | F28: Oil change + filter | G28: Routine / Wear Items | H28: Toyota of Columbus | I28: 72.21 | J28: INV-99353
A29: COLDRV5 18 HONDA ACCORD | B29: 45937 | C29: 70519 | D29: BREAK DOWN | E29: Vehicle wouldn't start | F29: Coolant flush | G29: Routine / Wear Items | H29: Discount Tire | I29: 141.68 | J29: INV-22833
A30: COLDRV8 21 TOY COR | B30: 45937 | C30: 49854 | D30: MAINTENANCE | F30: Radiator replacement | G30: Engine & Cooling | H30: Meineke | I30: 403.26 | J30: INV-83792
A31: COLDRV2 17 NISSAN ALTIMA | B31: 45947 | C31: 94164 | D31: MAINTENANCE | F31: Power steering fluid flush | G31: Steering & Suspension | H31: Jiffy Lube | I31: 132.58 | J31: INV-37869
A32: COLDRV4 2015 HONDA ACCORD | B32: 45962 | C32: 119868 | D32: MAINTENANCE | F32: Headlight bulb replacement | G32: Routine / Wear Items | H32: Meineke | I32: 34.39 | J32: INV-38864
A33: COLDRV8 21 TOY COR | B33: 45969 | C33: 50954 | D33: MAINTENANCE | F33: Brake pad replacement (rear) | G33: Routine / Wear Items | H33: Toyota of Columbus | I33: 281.32 | J33: INV-42018
A34: COLDRV4 2015 HONDA ACCORD | B34: 45982 | C34: 120958 | D34: REPAIR | F34: Brake pad replacement (front) | G34: Routine / Wear Items | H34: Jiffy Lube | I34: 306.76 | J34: INV-19287
A35: COLDRV1 22 TOY COR | B35: 45986 | C35: 39431 | D35: REPAIR | F35: Sway bar link replacement | G35: Steering & Suspension | H35: Toyota of Columbus | I35: 168.91 | J35: INV-59615
A36: COLDRV1 22 TOY COR | B36: 46016 | C36: 42492 | D36: MAINTENANCE | F36: Spark plug replacement | G36: Routine / Wear Items | H36: Pep Boys | I36: 154.25 | J36: INV-19116
A37: COLDRV3 17 TOY PRIUS | B37: 46017 | C37: 96891 | D37: MAINTENANCE | F37: Brake pad replacement (front) | G37: Routine / Wear Items | H37: Honda Service Center | I37: 221.09 | J37: INV-69470
A38: COLDRV5 18 HONDA ACCORD | B38: 46026 | C38: 71379 | D38: ACCIDENT | E38: Side mirror clipped | F38: Check engine light diagnosis | G38: Electrical & Other Major | H38: Midas Auto | I38: 96.55 | J38: INV-73653
A39: COLDRV8 21 TOY COR | B39: 46036 | C39: 52921 | D39: MAINTENANCE | F39: Clutch replacement | G39: Transmission & Drivetrain | H39: Discount Tire | I39: 1228.17 | J39: INV-11025
A40: COLDRV3 17 TOY PRIUS | B40: 46037 | C40: 100648 | D40: BREAK DOWN | E40: Strange noise from engine | F40: Motor mount replacement | G40: Engine & Cooling | H40: Discount Tire | I40: 440.49 | J40: INV-23947
A41: COLDRV4 2015 HONDA ACCORD | B41: 46067 | C41: 122732 | D41: MAINTENANCE | F41: Cabin air filter | G41: Routine / Wear Items | H41: Meineke | I41: 33.97 | J41: INV-85525
...

Sheet Vehicle Dashboard
A1: VEHICLE DASHBOARD
A2: Select a vehicle below to view its complete service profile • All data pulls from Service Log automatically
A4: SELECT VEHICLE: | B4: COLDRV1 22 TOY COR
A6: TOTAL SPENT | B6: # OF SERVICES | C6: AVG COST / SERVICE | D6: HIGHEST SINGLE COST | E6: LATEST MILEAGE | F6: FUEL EFFICIENCY
A7: =SUMIFS('Service Log'!I$2:I$500,'Service Log'!A$2:A$500,B4) | B7: =COUNTIFS('Service Log'!A$2:A$500,B4,'Service Log'!I$2:I$500,">0") | C7: =IFERROR(A7/B7,0) | D7: =IFERROR(maxifs('Service Log'!I$2:I$500,'Service Log'!A$2:A$500,B4),0) | E7: =IFERROR(maxifs('Service Log'!C$2:C$500,'Service Log'!A$2:A$500,B4),"") | F7: =IFERROR(SUMIFS('Fuel Log'!D$2:D$500,'Fuel Log'!A$2:A$500,B4)/SUMIFS('Fuel Log'!C$2:C$500,'Fuel Log'!A$2:A$500,B4),"")
A9: COST BY CATEGORY | D9: SERVICE TRIGGERS
A10: Routine / Wear Items | B10: =SUMIFS('Service Log'!I$2:I$500,'Service Log'!A$2:A$500,B4,'Service Log'!G$2:G$500,"Routine / Wear Items") | D10: MAINTENANCE | E10: =COUNTIFS('Service Log'!A$2:A$500,B4,'Service Log'!D$2:D$500,"MAINTENANCE")
A11: Engine & Cooling | B11: =SUMIFS('Service Log'!I$2:I$500,'Service Log'!A$2:A$500,B4,'Service Log'!G$2:G$500,"Engine & Cooling") | D11: REPAIR | E11: =COUNTIFS('Service Log'!A$2:A$500,B4,'Service Log'!D$2:D$500,"REPAIR")
A12: Transmission & Drivetrain | B12: =SUMIFS('Service Log'!I$2:I$500,'Service Log'!A$2:A$500,B4,'Service Log'!G$2:G$500,"Transmission & Drivetrain") | D12: BREAK DOWN | E12: =COUNTIFS('Service Log'!A$2:A$500,B4,'Service Log'!D$2:D$500,"BREAK DOWN")
A13: Steering & Suspension | B13: =SUMIFS('Service Log'!I$2:I$500,'Service Log'!A$2:A$500,B4,'Service Log'!G$2:G$500,"Steering & Suspension") | D13: ACCIDENT | E13: =COUNTIFS('Service Log'!A$2:A$500,B4,'Service Log'!D$2:D$500,"ACCIDENT")
A14: Electrical & Other Major | B14: =SUMIFS('Service Log'!I$2:I$500,'Service Log'!A$2:A$500,B4,'Service Log'!G$2:G$500,"Electrical & Other Major")
A16: RECENT SERVICE HISTORY (filtered from Service Log)
A17: DATE | B17: MILEAGE | C17: TRIGGER | D17: SERVICE CATEGORY | E17: COST | F17: NOTES
A18: =IFERROR(filter('Service Log'!B$2:B$500,'Service Log'!A$2:A$500=B4),"") | B18: =IFERROR(filter('Service Log'!C$2:C$500,'Service Log'!A$2:A$500=B4),"") | C18: =IFERROR(filter('Service Log'!D$2:D$500,'Service Log'!A$2:A$500=B4),"") | D18: =IFERROR(filter('Service Log'!G$2:G$500,'Service Log'!A$2:A$500=B4),"") | E18: =IFERROR(filter('Service Log'!I$2:I$500,'Service Log'!A$2:A$500=B4),"") | F18: =IFERROR(filter('Service Log'!E$2:E$500,'Service Log'!A$2:A$500=B4),"")

Sheet Fuel Log
A1: FUEL LOG — ALL VEHICLES
A2: Track fill-ups separately from service events • MPG calculates automatically • Filter by vehicle using column A
A3: VEHICLE | B3: DATE | C3: GALLONS | D3: MILES DRIVEN | E3: MPG | F3: COST / GALLON | G3: TOTAL FUEL COST
A4: COLDRV3 17 TOY PRIUS | B4: 45677 | C4: 9.28 | D4: 491.8 | E4: =IFERROR(D4/C4,"") | F4: 2.85 | G4: =IFERROR(C4*F4,"")
A5: COLDRV8 21 TOY COR | B5: 45683 | C5: 12.24 | D5: 373.3 | E5: =IFERROR(D5/C5,"") | F5: 3.17 | G5: =IFERROR(C5*F5,"")
A6: COLDRV5 18 HONDA ACCORD | B6: 45685 | C6: 7.64 | D6: 382.1 | E6: =IFERROR(D6/C6,"") | F6: 3.31 | G6: =IFERROR(C6*F6,"")
A7: COLDRV4 2015 HONDA ACCORD | B7: 45686 | C7: 14.21 | D7: 327.7 | E7: =IFERROR(D7/C7,"") | F7: 2.89 | G7: =IFERROR(C7*F7,"")
A8: COLDRV1 22 TOY COR | B8: 45688 | C8: 12.14 | D8: 370.2 | E8: =IFERROR(D8/C8,"") | F8: 2.96 | G8: =IFERROR(C8*F8,"")
A9: COLDRV2 17 NISSAN ALTIMA | B9: 45688 | C9: 10.39 | D9: 276.9 | E9: =IFERROR(D9/C9,"") | F9: 3.59 | G9: =IFERROR(C9*F9,"")
A10: COLDRV1 22 TOY COR | B10: 45696 | C10: 13.73 | D10: 338.8 | E10: =IFERROR(D10/C10,"") | F10: 2.97 | G10: =IFERROR(C10*F10,"")
A11: COLDRV4 2015 HONDA ACCORD | B11: 45696 | C11: 13.92 | D11: 268.2 | E11: =IFERROR(D11/C11,"") | F11: 2.96 | G11: =IFERROR(C11*F11,"")
A12: COLDRV3 17 TOY PRIUS | B12: 45698 | C12: 13.15 | D12: 487.4 | E12: =IFERROR(D12/C12,"") | F12: 3.6 | G12: =IFERROR(C12*F12,"")
A13: COLDRV5 18 HONDA ACCORD | B13: 45699 | C13: 7.54 | D13: 302.8 | E13: =IFERROR(D13/C13,"") | F13: 3.45 | G13: =IFERROR(C13*F13,"")
A14: COLDRV8 21 TOY COR | B14: 45701 | C14: 8.89 | D14: 314.7 | E14: =IFERROR(D14/C14,"") | F14: 3.51 | G14: =IFERROR(C14*F14,"")
A15: COLDRV1 22 TOY COR | B15: 45707 | C15: 11.73 | D15: 334.8 | E15: =IFERROR(D15/C15,"") | F15: 3.01 | G15: =IFERROR(C15*F15,"")
... A93: COLDRV3 17 TOY PRIUS | B93: 45968 | C93: 12.89 | D93: 371.3 | E93: =IFERROR(D93/C93,"") | F93: 3.19 | G93: =IFERROR(C93*F93,"")
E94: =IFERROR(D94/C94,"") | G94: =IFERROR(C94*F94,"")
E95: =IFERROR(D95/C95,"") | G95: =IFERROR(C95*F95,"")
E96: =IFERROR(D96/C96,"") | G96: =IFERROR(C96*F96,"")
E97: =IFERROR(D97/C97,"") | G97: =IFERROR(C97*F97,"")
E98: =IFERROR(D98/C98,"") | G98: =IFERROR(C98*F98,"")
E99: =IFERROR(D99/C99,"") | G99: =IFERROR(C99*F99,"")
E100: =IFERROR(D100/C100,"") | G100: =IFERROR(C100*F100,"")
E101: =IFERROR(D101/C101,"") | G101: =IFERROR(C101*F101,"")
E102: =IFERROR(D102/C102,"") | G102: =IFERROR(C102*F102,"")
E103: =IFERROR(D103/C103,"") | G103: =IFERROR(C103*F103,"")
E104: =IFERROR(D104/C104,"") | G104: =IFERROR(C104*F104,"")
E105: =IFERROR(D105/C105,"") | G105: =IFERROR(C105*F105,"")
... E500: =IFERROR(D500/C500,"") | G500: =IFERROR(C500*F500,"")

Sheet Major Systems Tracker
A1: MAJOR SYSTEMS & LIFE TRACKER
A2: Track significant system events: failures, repairs, replacements • Helps identify patterns and plan future costs
A3: VEHICLE | B3: DATE | C3: MILEAGE | D3: SYSTEM | E3: EVENT TYPE | F3: DESCRIPTION | G3: COST | H3: SHOP / VENDOR | I3: WARRANTY? | J3: WARRANTY EXPIRY
A4: COLDRV3 17 TOY PRIUS | B4: 45731 | C4: 91147 | D4: Alternator | E4: Replacement | F4: Battery not charging | G4: 745.45 | H4: Firestone | I4: Yes | J4: 46457
A5: COLDRV8 21 TOY COR | B5: 45740 | C5: 47074 | D5: Radiator | E5: Preventive | F5: Plastic end tank cracked | G5: 1510 | H5: Firestone | I5: No
A6: COLDRV5 18 HONDA ACCORD | B6: 45755 | C6: 73482 | D6: Radiator | E6: Inspection | F6: Coolant leak at seam | G6: 1284.19 | H6: Firestone | I6: No
A7: COLDRV1 22 TOY COR | B7: 45762 | C7: 39260 | D7: Radiator | E7: Preventive | F7: Plastic end tank cracked | G7: 1602.18 | H7: Discount Tire | I7: Yes | J7: 46471
A8: COLDRV3 17 TOY PRIUS | B8: 45796 | C8: 90361 | D8: Engine | E8: Failure | F8: Check engine light - P0301 | G8: 1300.74 | H8: Honda Service Center | I8: No
A9: COLDRV4 2015 HONDA ACCORD | B9: 45796 | C9: 124507 | D9: Braking System | E9: Preventive | F9: ABS light on | G9: 1429.89 | H9: Midas Auto | I9: No
A10: COLDRV1 22 TOY COR | B10: 45802 | C10: 49083 | D10: Alternator | E10: Inspection | F10: Whining noise from belt area | G10: 1066.04 | H10: Pep Boys | I10: No
A11: COLDRV2 17 NISSAN ALTIMA | B11: 45820 | C11: 102056 | D11: Engine | E11: Failure | F11: Check engine light - P0301 | G11: 515.63 | H11: Pep Boys | I11: No
A12: COLDRV5 18 HONDA ACCORD | B12: 45839 | C12: 69339 | D12: Transmission | E12: Preventive | F12: Fluid dark and burnt smell | G12: 1218.6 | H12: Firestone | I12: No
A13: COLDRV4 2015 HONDA ACCORD | B13: 45864 | C13: 113251 | D13: Braking System | E13: Inspection | F13: Grinding noise | G13: 1088.24 | H13: Quick Lube Express | I13: No
A14: COLDRV2 17 NISSAN ALTIMA | B14: 45897 | C14: 94528 | D14: Catalytic Converter | E14: Preventive | F14: Rattle from underneath | G14: 852.08 | H14: Discount Tire | I14: No
A15: COLDRV3 17 TOY PRIUS | B15: 45937 | C15: 93041 | D15: Engine | E15: Preventive | F15: Check engine light - P0301 | G15: 924.5 | H15: AAMCO | I15: No
A16: COLDRV3 17 TOY PRIUS | B16: 45973 | C16: 89427 | D16: Radiator | E16: Inspection | F16: Coolant leak at seam | G16: 1506.49 | H16: Midas Auto | I16: No
A17: COLDRV4 2015 HONDA ACCORD | B17: 45991 | C17: 115695 | D17: Alternator | E17: Repair | F17: Whining noise from belt area | G17: 1239.71 | H17: Honda Service Center | I17: No
A18: COLDRV2 17 NISSAN ALTIMA | B18: 46016 | C18: 93339 | D18: Catalytic Converter | E18: Replacement | F18: Rattle from underneath | G18: 564.82 | H18: Toyota of Columbus | I18: No
A19: COLDRV2 17 NISSAN ALTIMA | B19: 46061 | C19: 102319 | D19: Starter | E19: Repair | F19: Slow cranking | G19: 507.03 | H19: AAMCO | I19: No
A20: COLDRV3 17 TOY PRIUS | B20: 46076 | C20: 90881 | D20: Engine | E20: Repair | F20: Oil leak at valve cover | G20: 1488.38 | H20: Firestone | I20: Yes | J20: 46510
A21: COLDRV4 2015 HONDA ACCORD | B21: 46091 | C21: 119543 | D21: Transmission | E21: Repair | F21: Slipping between 2nd and 3rd | G21: 824.05 | H21: Meineke | I21: No

Sheet Category Guide
A1: SERVICE CATEGORY REFERENCE GUIDE
A2: Use this guide when choosing a Service Category on the Service Log
A4: CATEGORY | B4: INCLUDES | C4: TYPICAL EXAMPLES
A5: Routine / Wear Items | B5: Oil, filters, brakes, tires, bulbs, battery, wipers, alignments | C5: Oil changes, brake pads, new tires, headlight bulbs, wiper blades, battery replacement, alignment
A6: Engine & Cooling | B6: Engine internals, leaks, radiator, water pump, overheating, mounts | C6: Head gasket, radiator flush, water pump, thermostat, coolant leak repair, motor mount
A7: Transmission & Drivetrain | B7: Transmission, CV axles, torque converter, differential | C7: Transmission fluid, CV axle boot, torque converter, clutch, differential service
A8: Steering & Suspension | B8: Struts, control arms, wheel bearings, steering rack | C8: Strut replacement, control arm bushings, wheel bearing, tie rod, power steering
A9: Electrical & Other Major | B9: Alternator, starter, AC, sensors, catalytic converter, wiring | C9: Alternator, starter motor, AC recharge/compressor, O2 sensor, catalytic converter, wiring harness
A12: FLEET VEHICLES
A13: COLDRV1 22 TOY COR
A14: COLDRV2 17 NISSAN ALTIMA
A15: COLDRV3 17 TOY PRIUS
A16: COLDRV4 2015 HONDA ACCORD
A17: COLDRV5 18 HONDA ACCORD
A18: COLDRV8 21 TOY COR
